Workbook

Sheet Panel Data
A1: code | B1: country_num | C1: country code | D1: year | E1: Trade | F1: InTradeijt | G1: GDPi | H1: InGDPit | I1: GDPjt | J1: InGDPjt | K1: PGDPi | L1: InPGDPi | M1: PGDPj | N1: InPGDPj | O1: DIS | P1: InDIS | Q1: POPi | R1: InPOPi | S1: POPj | T1: InPOPj | U1: BORij | V1: FTAij | W1: TARIjt | X1: NTBjt | Y1: PCT | Z1: PCTjt | AA1: FTUjt | AB1: POLjt | AC1: EFjt
A2: 1 | B2: Japan | C2: =VLOOKUP(B2,'GDP Data1'!A:B,2,FALSE) -> JPN | D2: 2013 | E2: 1578105841 | F2: 21.179491 | G2: 9570470577245 | H2: 29.889703 | I2: 5.2123282e+12 | J2: 29.282048 | K2: 7020.3857 | L2: 8.8565734 | M2: 40898.648 | N2: 10.618852 | O2: 204811.25 | P2: 12.229844 | Q2: 1363240000 | R2: 21.03313 | S2: 127445000 | T2: 18.663195 | U2: 0 | V2: 0 | W2: 9.02 | X2: 6.9520557 | Y2: 21442040 | Z2: =Y2/1000000 -> 21.44204 | AA2: 50.140823 | AB2: 1.0191419 | AC2: 7.8651808
A3: 1 | B3: Japan | C3: =VLOOKUP(B3,'GDP Data1'!A:B,2,FALSE) -> JPN | D3: 2014 | E3: 1603313761 | F3: 21.195338 | G3: 10475624783236 | H3: 29.980072 | I3: 4.8969944e+12 | J3: 29.219643 | K3: 7636.0742 | L3: 8.9406389 | M3: 38475.395 | N3: 10.557774 | O3: 194756.36 | P3: 12.179505 | Q3: 1371860000 | R3: 21.039433 | S3: 127276000 | T3: 18.661869 | U3: 0 | V3: 0 | W3: 9.16 | X3: 6.9767983 | Y3: 21662814 | Z3: =Y3/1000000 -> 21.662814 | AA3: 49.858018 | AB3: 0.96859735 | AC3: 7.871887
A4: 1 | B4: Japan | C4: =VLOOKUP(B4,'GDP Data1'!A:B,2,FALSE) -> JPN | D4: 2015 | E4: 1882567071 | F4: 21.355902 | G4: 11061573199440 | H4: 30.034498 | I4: 4.4449307e+12 | J4: 29.122785 | K4: 8016.446 | L4: 8.9892505 | M4: 34960.639 | N4: 10.461978 | O4: 102099.71 | P4: 11.533705 | Q4: 1379860000 | R4: 21.045248 | S4: 127141000 | T4: 18.660807 | U4: 0 | V4: 0 | W4: 9.2 | X4: 7.2771305 | Y4: 21094824 | Z4: =Y4/1000000 -> 21.094824 | AA4: 50.062956 | AB4: 1.0542206 | AC4: 7.8585652
A5: 1 | B5: Japan | C5: =VLOOKUP(B5,'GDP Data1'!A:B,2,FALSE) -> JPN | D5: 2016 | E5: 1563575405 | F5: 21.170241 | G5: 11233314018690 | H5: 30.049905 | I5: 5.0036776e+12 | J5: 29.241194 | K5: 8094.3904 | L5: 8.9989266 | M5: 39375.473 | N5: 10.580898 | O5: 89697.64 | P5: 11.4042 | Q5: 1387790000 | R5: 21.050978 | S5: 127076000 | T5: 18.660296 | U5: 0 | V5: 0 | W5: 9.2 | X5: 7.5288242 | Y5: 21678076 | Z5: =Y5/1000000 -> 21.678076 | AA5: 50.498811 | AB5: 0.968189 | AC5: 7.8451529
A6: 1 | B6: Japan | C6: =VLOOKUP(B6,'GDP Data1'!A:B,2,FALSE) -> JPN | D6: 2017 | E6: 1875336826 | F6: 21.352054 | G6: 12310491176727 | H6: 30.141473 | I6: 4.9308374e+12 | J6: 29.22653 | K6: 8817.0455 | L6: 9.0844421 | M6: 38834.053 | N6: 10.567053 | O6: 106187.05 | P6: 11.572957 | Q6: 1396215000 | R6: 21.057031 | S6: 126972000 | T6: 18.659477 | U6: 0 | V6: 0 | W6: 9.2 | X6: 7.9267173 | Y6: 22795035 | Z6: =Y6/1000000 -> 22.795035 | AA6: 50.492045 | AB6: 1.1001265 | AC6: 7.8604688
A7: 1 | B7: Japan | C7: =VLOOKUP(B7,'GDP Data1'!A:B,2,FALSE) -> JPN | D7: 2018 | E7: 1823133584 | F7: 21.323823 | G7: 13894907485399 | H7: 30.262544 | I7: 5.0408809e+12 | J7: 29.248602 | K7: 9905.4061 | L7: 9.200836 | M7: 39751.133 | N7: 10.590394 | O7: 136344 | P7: 11.822936 | Q7: 1402760000 | R7: 21.061708 | S7: 126811000 | T7: 18.658208 | U7: 0 | V7: 0 | W7: 9.12 | X7: 7.803046 | Y7: 23424446 | Z7: =Y7/1000000 -> 23.424446 | AA7: 50.24941 | AB7: 1.0373586 | AC7: 8.2225143
A8: 1 | B8: Japan | C8: =VLOOKUP(B8,'GDP Data1'!A:B,2,FALSE) -> JPN | D8: 2019 | E8: 1875583973 | F8: 21.352186 | G8: 14279968485748 | H8: 30.289879 | I8: 5.1179939e+12 | J8: 29.263784 | K8: 10143.86 | L8: 9.2246239 | M8: 40415.957 | N8: 10.60698 | O8: 119121.73 | P8: 11.687901 | Q8: 1407745000 | R8: 21.065255 | S8: 126633000 | T8: 18.656804 | U8: 0 | V8: 0 | W8: 9.08 | X8: 7.803046 | Y8: 23276482 | Z8: =Y8/1000000 -> 23.276482 | AA8: 49.878655 | AB8: 1.019695 | AC8: 8.2225143
A9: 1 | B9: Japan | C9: =VLOOKUP(B9,'GDP Data1'!A:B,2,FALSE) -> JPN | D9: 2020 | E9: 1770605763 | F9: 21.294588 | G9: 14687743556970 | H9: 30.318034 | I9: 5.0487896e+12 | J9: 29.25017 | K9: 10408.719 | L9: 9.2503991 | M9: 39986.929 | N9: 10.596308 | O9: 81856.357 | P9: 11.312721 | Q9: 1411100000 | R9: 21.067635 | S9: 126261000 | T9: 18.653862 | U9: 0 | V9: 0 | W9: 9.12 | X9: 7.803046 | Y9: 21556531 | Z9: =Y9/1000000 -> 21.556531 | AA9: 49.485977 | AB9: 1.0260669 | AC9: 8.2225143
A10: 1 | B10: Japan | C10: =VLOOKUP(B10,'GDP Data1'!A:B,2,FALSE) -> JPN | D10: 2021 | E10: 2113999967 | F10: 21.471848 | G10: 17820459342451 | H10: 30.511368 | I10: 5.0055367e+12 | J10: 29.241566 | K10: 12617.505 | L10: 9.4428404 | M10: 39827.127 | N10: 10.592304 | O10: 142421.71 | P10: 11.866548 | Q10: 1412360000 | R10: 21.068528 | S10: 125681593 | T10: 18.649262 | U10: 0 | V10: 0 | W10: 9.16 | X10: 7.803046 | Y10: 22204259 | Z10: =Y10/1000000 -> 22.204259 | AA10: 49.42007 | AB10: 1.0153564 | AC10: 8.2225143
A11: 1 | B11: Japan | C11: =VLOOKUP(B11,'GDP Data1'!A:B,2,FALSE) -> JPN | D11: 2022 | E11: 3367103863 | F11: 21.937319 | G11: 17963170521080 | H11: 30.519345 | I11: 4.2311412e+12 | J11: 29.073493 | K11: 12720.216 | L11: 9.4509478 | M11: 33815.317 | N11: 10.428669 | O11: 198374.01 | P11: 12.197909 | Q11: 1412175000 | R11: 21.068397 | S11: 125124989 | T11: 18.644824 | U11: 0 | V11: 0 | W11: 9.14 | X11: 7.803046 | Y11: 22851987 | Z11: =Y11/1000000 -> 22.851987 | AA11: 48.987517 | AB11: 1.073911 | AC11: 8.02
A12: 2 | B12: Australia | C12: =VLOOKUP(B12,'GDP Data1'!A:B,2,FALSE) -> AUS | D12: 2013 | E12: 7943425 | F12: 15.887855 | G12: 9570470577245 | H12: 29.889703 | I12: 1.5763297e+12 | J12: 28.08612 | K12: 7020.3857 | L12: 8.8565734 | M12: 68156.386 | N12: 11.12956 | O12: 785944.95 | P12: 13.574642 | Q12: 1363240000 | R12: 21.03313 | S12: 23128129 | T12: 16.95656 | U12: 0 | V12: 1 | W12: 9.46 | X12: 7.5106768 | Y12: 7290251 | Z12: =Y12/1000000 -> 7.290251 | AA12: 44.782354 | AB12: 1.031073 | AC12: 9.2225448
A13: 2 | B13: Australia | C13: =VLOOKUP(B13,'GDP Data1'!A:B,2,FALSE) -> AUS | D13: 2014 | E13: 7905269 | F13: 15.88304 | G13: 10475624783236 | H13: 29.980072 | I13: 1.4675899e+12 | J13: 28.014643 | K13: 7636.0742 | L13: 8.9406389 | M13: 62515.315 | N13: 11.043167 | O13: 747360.19 | P13: 13.524303 | Q13: 1371860000 | R13: 21.039433 | S13: 23475686 | T13: 16.971476 | U13: 0 | V13: 1 | W13: 9.46 | X13: 8.062534 | Y13: 7432288 | Z13: =Y13/1000000 -> 7.432288 | AA13: 39.157072 | AB13: 1.032192 | AC13: 9.2225448
... A21: 2 | B21: Australia | C21: =VLOOKUP(B21,'GDP Data1'!A:B,2,FALSE) -> AUS | D21: 2022 | E21: 45407239 | F21: 17.631182 | G21: 17963170521080 | H21: 30.519345 | I21: 1.6754187e+12 | J21: 28.147084 | K21: 12720.216 | L21: 9.4509478 | M21: 64491.43 | N21: 11.074288 | O21: 761242.62 | P21: 13.542707 | Q21: 1412175000 | R21: 21.068397 | S21: 25978935 | T21: 17.072797 | U21: 1 | V21: 1 | W21: 9.4977778 | X21: 8.3163352 | Y21: 7840592 | Z21: =Y21/1000000 -> 7.840592 | AA21: 24.483989 | AB21: 0.93357205 | AC21: 8.88
A22: 3 | B22: Brunei | C22: BRN | D22: 2013 | E22: 2387 | F22: 7.7777926 | G22: 9570470577245 | H22: 29.889703 | I22: 1.8094326e+10 | J22: 23.618864 | K22: 7020.3857 | L22: 8.8565734 | M22: 43950.057 | N22: 10.690809 | O22: 291248.08 | P22: 12.581931 | Q22: 1363240000 | R22: 21.03313 | S22: 411702 | T22: 12.928055 | U22: 0 | V22: 0 | W22: 9.5 | X22: 7.0996252 | Y22: 111817 | Z22: =Y22/1000000 -> 0.111817 | AA22: 16.355988 | AB22: 1.0740223 | AC22: 7.0584804
A23: 3 | B23: Brunei | C23: BRN | D23: 2014 | E23: 20986 | F23: 9.9516108 | G23: 10475624783236 | H23: 29.980072 | I23: 1.7097801e+10 | J23: 23.562216 | K23: 7636.0742 | L23: 8.9406389 | M23: 41035.773 | N23: 10.622199 | O23: 276949.71 | P23: 12.531591 | Q23: 1371860000 | R23: 21.039433 | S23: 416656 | T23: 12.940016 | U23: 0 | V23: 0 | W23: 9.76 | X23: 4.7752686 | Y23: 106168 | Z23: =Y23/1000000 -> 0.106168 | AA23: 17.195 | AB23: 1.261507 | AC23: 7.8083609
A24: 3 | B24: Brunei | C24: BRN | D24: 2015 | E24: 221378 | F24: 12.307627 | G24: 11061573199440 | H24: 30.034498 | I24: 1.2930293e+10 | J24: 23.282839 | K24: 8016.446 | L24: 8.9892505 | M24: 30681.437 | N24: 10.331413 | O24: 145189.02 | P24: 11.885792 | Q24: 1379860000 | R24: 21.045248 | S24: 421437 | T24: 12.951426 | U24: 0 | V24: 0 | W24: 9.76 | X24: 4.0546789 | Y24: 102798 | Z24: =Y24/1000000 -> 0.102798 | AA24: 18.034012 | AB24: 1.2337126 | AC24: 8.1587013
A25: 3 | B25: Brunei | C25: BRN | D25: 2016 | E25: 25337 | F25: 10.140021 | G25: 11233314018690 | H25: 30.049905 | I25: 1.1400467e+10 | J25: 23.15692 | K25: 8094.3904 | L25: 8.9989266 | M25: 26762.037 | N25: 10.19474 | O25: 127552.88 | P25: 11.756286 | Q25: 1387790000 | R25: 21.050978 | S25: 425994 | T25: 12.962181 | U25: 0 | V25: 0 | W25: 9.76 | X25: 4.2592272 | Y25: 98606 | Z25: =Y25/1000000 -> 0.098606 | AA25: 17.421137 | AB25: 1.1420178 | AC25: 8.1176436
A26: 3 | B26: Brunei | C26: BRN | D26: 2017 | E26: 3819 | F26: 8.2477439 | G26: 12310491176727 | H26: 30.141473 | I26: 1.2128182e+10 | J26: 23.218798 | K26: 8817.0455 | L26: 9.0844421 | M26: 28186.983 | N26: 10.246616 | O26: 151001.35 | P26: 11.925044 | Q26: 1396215000 | R26: 21.057031 | S26: 430276 | T26: 12.972182 | U26: 0 | V26: 0 | W26: 9.96 | X26: 4.3983561 | Y26: 104747 | Z26: =Y26/1000000 -> 0.104747 | AA26: 19.474477 | AB26: 1.1534252 | AC26: 7.1301135
A27: 3 | B27: Brunei | C27: BRN | D27: 2018 | E27: 20228 | F27: 9.9148231 | G27: 13894907485399 | H27: 30.262544 | I27: 1.3567164e+10 | J27: 23.330918 | K27: 9905.4061 | L27: 9.200836 | M27: 31241.024 | N27: 10.349487 | O27: 193885.48 | P27: 12.175023 | Q27: 1402760000 | R27: 21.061708 | S27: 434274 | T27: 12.981431 | U27: 0 | V27: 0 | W27: 9.96 | X27: 4.3180567 | Y27: 113125 | Z27: =Y27/1000000 -> 0.113125 | AA27: 19.017487 | AB27: 1.2358136 | AC27: 7.1302614
A28: 3 | B28: Brunei | C28: BRN | D28: 2019 | E28: 19692 | F28: 9.8879677 | G28: 14279968485748 | H28: 30.289879 | I28: 1.346924e+10 | J28: 23.323674 | K28: 10143.86 | L28: 9.2246239 | M28: 30748.32 | N28: 10.333591 | O28: 169394.87 | P28: 12.039988 | Q28: 1407745000 | R28: 21.065255 | S28: 438048 | T28: 12.990084 | U28: 0 | V28: 0 | W28: 9.94 | X28: 4.3180567 | Y28: 117901 | Z28: =Y28/1000000 -> 0.117901 | AA28: 19.76724 | AB28: 1.1109637 | AC28: 7.1302614
A29: 3 | B29: Brunei | C29: BRN | D29: 2020 | E29: 20841 | F29: 9.9446775 | G29: 14687743556970 | H29: 30.318034 | I29: 1.2005796e+10 | J29: 23.208655 | K29: 10408.719 | L29: 9.2503991 | M29: 27179.344 | N29: 10.210213 | O29: 116402.33 | P29: 11.664808 | Q29: 1411100000 | R29: 21.067635 | S29: 441725 | T29: 12.998443 | U29: 0 | V29: 0 | W29: 9.96 | X29: 4.3180567 | Y29: 106174 | Z29: =Y29/1000000 -> 0.106174 | AA29: 23.518026 | AB29: 1.1879984 | AC29: 7.1302614
A30: 3 | B30: Brunei | C30: BRN | D30: 2021 | E30: 13242 | F30: 9.4911489 | G30: 17820459342451 | H30: 30.511368 | I30: 1.4006497e+10 | J30: 23.362787 | K30: 12617.505 | L30: 9.4428404 | M30: 31448.914 | N30: 10.35612 | O30: 202528.18 | P30: 12.218634 | Q30: 1412360000 | R30: 21.068528 | S30: 445373 | T30: 13.006667 | U30: 0 | V30: 0 | W30: 9.94 | X30: 4.3180567 | Y30: 94447 | Z30: =Y30/1000000 -> 0.094447 | AA30: 25.214371 | AB30: 1.1716517 | AC30: 7.1302614
A31: 3 | B31: Brunei | C31: BRN | D31: 2022 | E31: 85551 | F31: 11.356868 | G31: 17963170521080 | H31: 30.519345 | I31: 1.6681532e+10 | J31: 23.537568 | K31: 12720.216 | L31: 9.4509478 | M31: 37152.466 | N31: 10.522785 | O31: 282094.13 | P31: 12.549996 | Q31: 1412175000 | R31: 21.068397 | S31: 449002 | T31: 13.014783 | U31: 0 | V31: 0 | W31: 9.8377778 | X31: 4.65 | Y31: 82720 | Z31: =Y31/1000000 -> 0.08272 | AA31: 27.216805 | AB31: 1.257368 | AC31: 7.42
A32: 4 | B32: Canada | C32: =VLOOKUP(B32,'GDP Data1'!A:B,2,FALSE) -> CAN | D32: 2013 | E32: 17651000 | F32: 16.686303 | G32: 9570470577245 | H32: 29.889703 | I32: 1.8465974e+12 | J32: 28.244366 | K32: 7020.3857 | L32: 8.8565734 | M32: 52635.175 | N32: 10.87114 | O32: 984689.72 | P32: 13.800082 | Q32: 1363240000 | R32: 21.03313 | S32: 35082954 | T32: 17.373226 | U32: 0 | V32: 0 | W32: 9.16 | X32: 8.1541863 | Y32: 5260202 | Z32: =Y32/1000000 -> 5.260202 | AA32: 48.257897 | AB32: 1.0614218 | AC32: 7.4377159
A33: 4 | B33: Canada | C33: =VLOOKUP(B33,'GDP Data1'!A:B,2,FALSE) -> CAN | D33: 2014 | E33: 17686756 | F33: 16.688327 | G33: 10475624783236 | H33: 29.980072 | I33: 1.8057499e+12 | J33: 28.221997 | K33: 7636.0742 | L33: 8.9406389 | M33: 50955.998 | N33: 10.838718 | O33: 936347.9 | P33: 13.749742 | Q33: 1371860000 | R33: 21.039433 | S33: 35437435 | T33: 17.383279 | U33: 0 | V33: 0 | W33: 9.16 | X33: 9.3405814 | Y33: 5447571 | Z33: =Y33/1000000 -> 5.447571 | AA33: 46.331822 | AB33: 1.1755038 | AC33: 7.4834016
A34: 4 | B34: Canada | C34: =VLOOKUP(B34,'GDP Data1'!A:B,2,FALSE) -> CAN | D34: 2015 | E34: 19936988 | F34: 16.808087 | G34: 11061573199440 | H34: 30.034498 | I34: 1.5565088e+12 | J34: 28.073466 | K34: 8016.446 | L34: 8.9892505 | M34: 43596.136 | N34: 10.682724 | O34: 490874.1 | P34: 13.103943 | Q34: 1379860000 | R34: 21.045248 | S34: 35702908 | T34: 17.390743 | U34: 0 | V34: 0 | W34: 9.16 | X34: 8.8341172 | Y34: 5828525 | Z34: =Y34/1000000 -> 5.828525 | AA34: 43.692533 | AB34: 1.2623369 | AC34: 7.4834016
A35: 4 | B35: Canada | C35: =VLOOKUP(B35,'GDP Data1'!A:B,2,FALSE) -> CAN | D35: 2016 | E35: 21496945 | F35: 16.883421 | G35: 11233314018690 | H35: 30.049905 | I35: 1.5279947e+12 | J35: 28.054977 | K35: 8094.3904 | L35: 8.9989266 | M35: 42315.604 | N35: 10.652911 | O35: 431247.52 | P35: 12.974437 | Q35: 1387790000 | R35: 21.050978 | S35: 36109487 | T35: 17.402066 | U35: 0 | V35: 0 | W35: 9.18 | X35: 8.9711207 | Y35: 5727822 | Z35: =Y35/1000000 -> 5.727822 | AA35: 41.966319 | AB35: 1.2404116 | AC35: 7.4828586
A36: 4 | B36: Canada | C36: =VLOOKUP(B36,'GDP Data1'!A:B,2,FALSE) -> CAN | D36: 2017 | E36: 15072124 | F36: 16.528358 | G36: 12310491176727 | H36: 30.141473 | I36: 1.6492656e+12 | J36: 28.131351 | K36: 8817.0455 | L36: 9.0844421 | M36: 45129.429 | N36: 10.71729 | O36: 510525.18 | P36: 13.143195 | Q36: 1396215000 | R36: 21.057031 | S36: 36545236 | T36: 17.414061 | U36: 0 | V36: 0 | W36: 9.2 | X36: 8.9115793 | Y36: 6377236 | Z36: =Y36/1000000 -> 6.377236 | AA36: 39.582159 | AB36: 1.0896796 | AC36: 7.9055849
A37: 4 | B37: Canada | C37: =VLOOKUP(B37,'GDP Data1'!A:B,2,FALSE) -> CAN | D37: 2018 | E37: 19638763 | F37: 16.793016 | G37: 13894907485399 | H37: 30.262544 | I37: 1.7252979e+12 | J37: 28.176421 | K37: 9905.4061 | L37: 9.200836 | M37: 46547.795 | N37: 10.748235 | O37: 655513.47 | P37: 13.393174 | Q37: 1402760000 | R37: 21.061708 | S37: 37065084 | T37: 17.428186 | U37: 0 | V37: 0 | W37: 9.2 | X37: 8.9289801 | Y37: 6763247 | Z37: =Y37/1000000 -> 6.763247 | AA37: 37.375199 | AB37: 0.96377438 | AC37: 7.9055849
A38: 4 | B38: Canada | C38: =VLOOKUP(B38,'GDP Data1'!A:B,2,FALSE) -> CAN | D38: 2019 | E38: 32785119 | F38: 17.305485 | G38: 14279968485748 | H38: 30.289879 | I38: 1.7437252e+12 | J38: 28.187045 | K38: 10143.86 | L38: 9.2246239 | M38: 46374.153 | N38: 10.744498 | O38: 572712.41 | P38: 13.258139 | Q38: 1407745000 | R38: 21.065255 | S38: 37601230 | T38: 17.442547 | U38: 0 | V38: 0 | W38: 9.22 | X38: 8.9289801 | Y38: 7000133 | Z38: =Y38/1000000 -> 7.000133 | AA38: 36.234178 | AB38: 0.99481791 | AC38: 7.9055849
A39: 4 | B39: Canada | C39: =VLOOKUP(B39,'GDP Data1'!A:B,2,FALSE) -> CAN | D39: 2020 | E39: 36597701 | F39: 17.415496 | G39: 14687743556970 | H39: 30.318034 | I39: 1.6475984e+12 | J39: 28.13034 | K39: 10408.719 | L39: 9.2503991 | M39: 43349.678 | N39: 10.677055 | O39: 393548.27 | P39: 12.882959 | Q39: 1411100000 | R39: 21.067635 | S39: 38007166 | T39: 17.453285 | U39: 0 | V39: 0 | W39: 9.22 | X39: 8.9289801 | Y39: 6298023 | Z39: =Y39/1000000 -> 6.298023 | AA39: 35.208382 | AB39: 1.0131047 | AC39: 7.9055849
A40: 4 | B40: Canada | C40: =VLOOKUP(B40,'GDP Data1'!A:B,2,FALSE) -> CAN | D40: 2021 | E40: 49724954 | F40: 17.722017 | G40: 17820459342451 | H40: 30.511368 | I40: 2.0014867e+12 | J40: 28.324911 | K40: 12617.505 | L40: 9.4428404 | M40: 52358.622 | N40: 10.865872 | O40: 684733.83 | P40: 13.436785 | Q40: 1412360000 | R40: 21.068528 | S40: 38226498 | T40: 17.459039 | U40: 0 | V40: 0 | W40: 9.2 | X40: 8.9289801 | Y40: 7169607 | Z40: =Y40/1000000 -> 7.169607 | AA40: 30.881919 | AB40: 0.96219599 | AC40: 8.0196838
A41: 4 | B41: Canada | C41: =VLOOKUP(B41,'GDP Data1'!A:B,2,FALSE) -> CAN | D41: 2022 | E41: 102281773 | F41: 18.443242 | G41: 17963170521080 | H41: 30.519345 | I41: 2.13984e+12 | J41: 28.391752 | K41: 12720.216 | L41: 9.4509478 | M41: 54966.489 | N41: 10.914479 | O41: 953740.83 | P41: 13.768147 | Q41: 1412175000 | R41: 21.068397 | S41: 38929902 | T41: 17.477273 | U41: 0 | V41: 0 | W41: 9.1888889 | X41: 8.9289801 | Y41: 8041191 | Z41: =Y41/1000000 -> 8.041191 | AA41: 29.416716 | AB41: 0.77281404 | AC41: 7.73
A42: 5 | B42: Chile | C42: =VLOOKUP(B42,'GDP Data1'!A:B,2,FALSE) -> CHL | D42: 2013 | E42: 177739 | F42: 12.088071 | G42: 9570470577245 | H42: 29.889703 | I42: 2.7723947e+11 | J42: 26.348147 | K42: 7020.3857 | L42: 8.8565734 | M42: 15833.276 | N42: 9.6698691 | O42: 1836299.1 | P42: 14.423263 | Q42: 1363240000 | R42: 21.03313 | S42: 17509925 | T42: 16.678278 | U42: 0 | V42: 1 | W42: 8.8 | X42: 7.58983 | Y42: 3853407 | Z42: =Y42/1000000 -> 3.853407 | AA42: 19.116193 | AB42: 0.36374253 | AC42: 8.9082412
A43: 5 | B43: Chile | C43: =VLOOKUP(B43,'GDP Data1'!A:B,2,FALSE) -> CHL | D43: 2014 | E43: 185124 | F43: 12.128781 | G43: 10475624783236 | H43: 29.980072 | I43: 2.5940519e+11 | J43: 26.281657 | K43: 7636.0742 | L43: 8.9406389 | M43: 14666.343 | N43: 9.5933106 | O43: 1746148.9 | P43: 14.372923 | Q43: 1371860000 | R43: 21.039433 | S43: 17687108 | T43: 16.688347 | U43: 0 | V43: 0 | W43: 8.8 | X43: 8.4147994 | Y43: 3956160 | Z43: =Y43/1000000 -> 3.95616 | AA43: 19.379929 | AB43: 0.44751692 | AC43: 8.9083317
... A101: 10 | B101: Singapore | C101: =VLOOKUP(B101,'GDP Data1'!A:B,2,FALSE) -> SGP | D101: 2022 | E101: 5795002678 | F101: 22.480262 | G101: 17963170521080 | H101: 30.519345 | I101: 4.6678854e+11 | J101: 26.869142 | K101: 12720.216 | L101: 9.4509478 | M101: 82807.649 | N101: 11.324276 | O101: 367687.47 | P101: 12.814989 | Q101: 1412175000 | R101: 21.068397 | S101: 5637022 | T101: 15.544866 | U101: 0 | V101: 1 | W101: 9.9866667 | X101: 9.1933784 | Y101: 38069100 | Z101: =Y101/1000000 -> 38.0691 | AA101: 31.899256 | AB101: 1.4599425 | AC101: 8.76
A102: 11 | B102: Viet Nam | C102: VNM | D102: 2013 | E102: 1010025837 | F102: 20.733242 | G102: 9570470577245 | H102: 29.889703 | I102: 2.1370883e+11 | J102: 26.08788 | K102: 7020.3857 | L102: 8.8565734 | M102: 2367.4995 | N102: 7.7695896 | O102: 218725.69 | P102: 12.295574 | Q102: 1363240000 | R102: 21.03313 | S102: 90267739 | T102: 18.318291 | U102: 1 | V102: 0 | W102: 8.1 | X102: 6.3328075 | Y102: 8035812 | Z102: =Y102/1000000 -> 8.035812 | AA102: 7.4504237 | AB102: 0.25057727 | AC102: 6.5202541
A103: 11 | B103: Viet Nam | C103: VNM | D103: 2014 | E103: 531131536 | F103: 20.09052 | G103: 10475624783236 | H103: 29.980072 | I103: 2.3345148e+11 | J103: 26.17624 | K103: 7636.0742 | L103: 8.9406389 | M103: 2558.7789 | N103: 7.8472854 | O103: 207987.69 | P103: 12.245234 | Q103: 1371860000 | R103: 21.039433 | S103: 91235504 | T103: 18.328955 | U103: 1 | V103: 0 | W103: 8.1 | X103: 4.8509017 | Y103: 9473429 | Z103: =Y103/1000000 -> 9.473429 | AA103: 7.3713946 | AB103: -0.022347357 | AC103: 6.1977032
A104: 11 | B104: Viet Nam | C104: VNM | D104: 2015 | E104: 582022277 | F104: 20.182019 | G104: 11061573199440 | H104: 30.034498 | I104: 2.3925834e+11 | J104: 26.20081 | K104: 8016.446 | L104: 8.9892505 | M104: 2595.235 | N104: 7.8614323 | O104: 109036.15 | P104: 11.599435 | Q104: 1379860000 | R104: 21.045248 | S104: 92191398 | T104: 18.339377 | U104: 1 | V104: 0 | W104: 7.16 | X104: 5.3045213 | Y104: 10615391 | Z104: =Y104/1000000 -> 10.615391 | AA104: 7.9453693 | AB104: 0.063808225 | AC104: 6.1696223
...

Sheet Trade data
B1: 2013 | C1: 2014 | D1: 2015 | E1: 2016 | F1: 2017 | G1: 2018 | H1: 2019 | I1: 2020 | J1: 2021 | K1: 2022
A2: Japan | B2: 1578105841 | C2: 1603313761 | D2: 1882567071 | E2: 1563575405 | F2: 1875336826 | G2: 1823133584 | H2: 1875583973 | I2: 1770605763 | J2: 2113999967 | K2: 3367103863
A3: Australia | B3: 7943425 | C3: 7905269 | D3: 6562834 | E3: 5556350 | F3: 3319391 | G3: 4265130 | H3: 7659634 | I3: 11748860 | J3: 14536431 | K3: 45407239
A4: Brunei | B4: 2387 | C4: 20986 | D4: 221378 | E4: 25337 | F4: 3819 | G4: 20228 | H4: 19692 | I4: 20841 | J4: 13242 | K4: 85551
A5: Canada | B5: 17651000 | C5: 17686756 | D5: 19936988 | E5: 21496945 | F5: 15072124 | G5: 19638763 | H5: 32785119 | I5: 36597701 | J5: 49724954 | K5: 102281773
A6: Chile | B6: 177739 | C6: 185124 | D6: 42720 | E6: 302386 | F6: 184273 | G6: 513374 | H6: 659932 | I6: 348099 | J6: 602343 | K6: 802627
A7: Malaysia | B7: 2577758353 | C7: 3036501061 | D7: 2580228717 | E7: 2103410812 | F7: 4075830116 | G7: 5494966395 | H7: 6239931604 | I7: 6527460719 | J7: 9375706717 | K7: 12068973243
A8: Mexico | B8: 133508996 | C8: 138895969 | D8: 97876330 | E8: 93800994 | F8: 99475387 | G8: 257548595 | H8: 446522162 | I8: 432802729 | J8: 742098008 | K8: 1001436251
A9: New Zealand | B9: 775365 | C9: 984107 | D9: 632985 | E9: 125078 | F9: 153815 | G9: 935598 | H9: 455992 | I9: 1133608 | J9: 1256667 | K9: 3061579
A10: Peru | B10: 21715 | C10: 150001 | D10: 163086 | E10: 73569 | F10: 181353 | G10: 202452 | H10: 527359 | I10: 553837 | J10: 344943 | K10: 605810
A11: Singapore | B11: 4295261370 | C11: 4193038960 | D11: 5065419446 | E11: 3538177077 | F11: 3776416093 | G11: 3890321814 | H11: 3811357742 | I11: 5085616398 | J11: 5399921776 | K11: 5795002678
A12: Vietnam | B12: 1010025837 | C12: 531131536 | D12: 582022277 | E12: 1340006465 | F12: 4012268948 | G12: 5761936914 | H12: 9916482381 | I12: 13388712775 | J12: 13963172367 | K12: 12552810750

Sheet GDP Data1
A1: Data Source | B1: World Development Indicators
A2: Last Updated Date | B2: 45188
A4: Country Name | B4: Country Code | C4: Indicator Name | D4: Indicator Code | E4: 1960 | F4: 1961 | G4: 1962 | H4: 1963 | I4: 1964 | J4: 1965 | K4: 1966 | L4: 1967 | M4: 1968 | N4: 1969 | O4: 1970 | P4: 1971 | Q4: 1972 | R4: 1973 | S4: 1974 | T4: 1975 | U4: 1976 | V4: 1977 | W4: 1978 | X4: 1979 | Y4: 1980 | Z4: 1981 | AA4: 1982 | AB4: 1983 | AC4: 1984 | AD4: 1985 | AE4: 1986 | AF4: 1987 | AG4: 1988 | AH4: 1989 | AI4: 1990 | AJ4: 1991 | AK4: 1992 | AL4: 1993 | AM4: 1994 | AN4: 1995 | AO4: 1996 | AP4: 1997 | AQ4: 1998 | AR4: 1999 | AS4: 2000 | AT4: 2001 | AU4: 2002 | AV4: 2003 | AW4: 2004 | AX4: 2005 | AY4: 2006 | AZ4: 2007 | BA4: 2008 | BB4: 2009 | BC4: 2010 | BD4: 2011 | BE4: 2012 | BF4: 2013 | BG4: 2014 | BH4: 2015 | BI4: 2016 | BJ4: 2017 | BK4: 2018 | BL4: 2019 | BM4: 2020 | BN4: 2021 | BO4: 2022
A5: Aruba | B5: ABW | C5: GDP (current US$) | D5: NY.GDP.MKTP.CD | AE5: 4.0558659e+08 | AF5: 4.877095e+08 | AG5: 5.9664804e+08 | AH5: 6.9553073e+08 | AI5: 7.6480447e+08 | AJ5: 8.7206704e+08 | AK5: 9.5865922e+08 | AL5: 1.0832402e+09 | AM5: 1.2458101e+09 | AN5: 1.3206704e+09 | AO5: 1.3798883e+09 | AP5: 1.5318436e+09 | AQ5: 1.6653631e+09 | AR5: 1.722905e+09 | AS5: 1.8731844e+09 | AT5: 1.896648e+09 | AU5: 1.9620112e+09 | AV5: 2.0441341e+09 | AW5: 2.2547486e+09 | AX5: 2.3597765e+09 | AY5: 2.4698324e+09 | AZ5: 2.6776536e+09 | BA5: 2.8430168e+09 | BB5: 2.5536313e+09 | BC5: 2.4536313e+09 | BD5: 2.6379888e+09 | BE5: 2.6150838e+09 | BF5: 2.727933e+09 | BG5: 2.7910615e+09 | BH5: 2.9631285e+09 | BI5: 2.9837989e+09 | BJ5: 3.0921788e+09 | BK5: 3.2761877e+09 | BL5: 3.3957939e+09 | BM5: 2.6100389e+09 | BN5: 3.1260194e+09
A6: Africa Eastern and Southern | B6: AFE | C6: GDP (current US$) | D6: NY.GDP.MKTP.CD | E6: 2.1125015e+10 | F6: 2.1616228e+10 | G6: 2.350628e+10 | H6: 2.804836e+10 | I6: 2.5920665e+10 | J6: 2.9472103e+10 | K6: 3.2014368e+10 | L6: 3.326951e+10 | M6: 3.6327785e+10 | N6: 4.1638968e+10 | O6: 4.4629892e+10 | P6: 4.9173372e+10 | Q6: 5.312346e+10 | R6: 6.9482723e+10 | S6: 8.5380645e+10 | T6: 9.0835426e+10 | U6: 9.0212747e+10 | V6: 1.0224058e+11 | W6: 1.1608464e+11 | X6: 1.3425683e+11 | Y6: 1.7121779e+11 | Z6: 1.7585926e+11 | AA6: 1.6809566e+11 | AB6: 1.7556491e+11 | AC6: 1.6064675e+11 | AD6: 1.3675944e+11 | AE6: 1.5305034e+11 | AF6: 1.8665848e+11 | AG6: 2.0476599e+11 | AH6: 2.1824161e+11 | AI6: 2.5406209e+11 | AJ6: 2.7685673e+11 | AK6: 2.4608812e+11 | AL6: 2.4292641e+11 | AM6: 2.3961068e+11 | AN6: 2.7032715e+11 | AO6: 2.6949083e+11 | AP6: 2.8344622e+11 | AQ6: 2.6665233e+11 | AR6: 2.6302479e+11 | AS6: 2.8475932e+11 | AT6: 2.5964312e+11 | AU6: 2.6652943e+11 | AV6: 3.5417677e+11 | AW6: 4.404818e+11 | AX6: 5.1394163e+11 | AY6: 5.7758693e+11 | AZ6: 6.6286804e+11 | BA6: 7.1053623e+11 | BB6: 7.2190117e+11 | BC6: 8.6351954e+11 | BD6: 9.6782457e+11 | BE6: 9.7535478e+11 | BF6: 9.8598713e+11 | BG6: 1.0065264e+12 | BH6: 9.2734847e+11 | BI6: 8.8517643e+11 | BJ6: 1.0210432e+12 | BK6: 1.0071962e+12 | BL6: 1.0008341e+12 | BM6: 9.2759332e+11 | BN6: 1.0819981e+12 | BO6: 1.1694837e+12
A7: Afghanistan | B7: AFG | C7: GDP (current US$) | D7: NY.GDP.MKTP.CD | E7: 5.3777781e+08 | F7: 5.488889e+08 | G7: 5.4666668e+08 | H7: 7.5111119e+08 | I7: 8.0000004e+08 | J7: 1.0066666e+09 | K7: 1.4e+09 | L7: 1.6733334e+09 | M7: 1.3733334e+09 | N7: 1.4088889e+09 | O7: 1.7488866e+09 | P7: 1.831109e+09 | Q7: 1.5955555e+09 | R7: 1.7333333e+09 | S7: 2.1555555e+09 | T7: 2.3666666e+09 | U7: 2.5555556e+09 | V7: 2.9533334e+09 | W7: 3.3000001e+09 | X7: 3.6979404e+09 | Y7: 3.6417233e+09 | Z7: 3.4787879e+09 | AU7: 3.8542353e+09 | AV7: 4.5394966e+09 | AW7: 5.220825e+09 | AX7: 6.2261989e+09 | AY7: 6.9713833e+09 | AZ7: 9.7157651e+09 | BA7: 1.024977e+10 | BB7: 1.2154836e+10 | BC7: 1.5633844e+10 | BD7: 1.8190414e+10 | BE7: 2.0203573e+10 | BF7: 2.0564485e+10 | BG7: 2.0550583e+10 | BH7: 1.9998144e+10 | BI7: 1.8019554e+10 | BJ7: 1.8896353e+10 | BK7: 1.841886e+10 | BL7: 1.8904502e+10 | BM7: 2.0143452e+10 | BN7: 1.4583135e+10
A8: Africa Western and Central | B8: AFW | C8: GDP (current US$) | D8: NY.GDP.MKTP.CD | E8: 1.0447638e+10 | F8: 1.1173212e+10 | G8: 1.1990534e+10 | H8: 1.2727688e+10 | I8: 1.3898109e+10 | J8: 1.4929792e+10 | K8: 1.5910838e+10 | L8: 1.451058e+10 | M8: 1.4968236e+10 | N8: 1.6979316e+10 | O8: 2.3596164e+10 | P8: 2.0936359e+10 | Q8: 2.5386169e+10 | R8: 3.1975595e+10 | S8: 4.4416677e+10 | T8: 5.166719e+10 | U8: 6.2351622e+10 | V8: 6.5595123e+10 | W8: 7.1496497e+10 | X8: 8.8948338e+10 | Y8: 1.1243913e+11 | Z8: 2.1133806e+11 | AA8: 1.8744872e+11 | AB8: 1.3838418e+11 | AC8: 1.1451635e+11 | AD8: 1.16777e+11 | AE8: 1.0788651e+11 | AF8: 1.1072883e+11 | AG8: 1.0943885e+11 | AH8: 1.02255e+11 | AI8: 1.2238735e+11 | AJ8: 1.180397e+11 | AK8: 1.1889309e+11 | AL8: 9.927218e+10 | AM8: 8.66364e+10 | AN8: 1.0869089e+11 | AO8: 1.2628729e+11 | AP8: 1.2760239e+11 | AQ8: 1.3067813e+11 | AR8: 1.3808597e+11 | AS8: 1.4094576e+11 | AT8: 1.4852952e+11 | AU8: 1.7720116e+11 | AV8: 2.0521447e+11 | AW8: 2.542648e+11 | AX8: 3.1088958e+11 | AY8: 3.9692104e+11 | AZ8: 4.6548553e+11 | BA8: 5.6779116e+11 | BB8: 5.0836273e+11 | BC8: 5.9852156e+11 | BD8: 6.8201586e+11 | BE8: 7.3758947e+11 | BF8: 8.3394805e+11 | BG8: 8.9432248e+11 | BH8: 7.6864474e+11 | BI8: 6.9136341e+11 | BJ8: 6.8489876e+11 | BK8: 7.6702574e+11 | BL8: 8.2253839e+11 | BM8: 7.8646004e+11 | BN8: 8.4445972e+11 | BO8: 8.7786328e+11
A9: Angola | B9: AGO | C9: GDP (current US$) | D9: NY.GDP.MKTP.CD | Y9: 5.9305034e+09 | Z9: 5.550483e+09 | AA9: 5.550483e+09 | AB9: 5.7843416e+09 | AC9: 6.1314751e+09 | AD9: 7.5540654e+09 | AE9: 7.0725361e+09 | AF9: 8.0844124e+09 | AG9: 8.7698368e+09 | AH9: 1.0201781e+10 | AI9: 1.1229516e+10 | AJ9: 1.2704559e+10 | AK9: 1.5114352e+10 | AL9: 1.1051939e+10 | AM9: 3390500000 | AN9: 5.5612222e+09 | AO9: 7.526964e+09 | AP9: 7.6483774e+09 | AQ9: 6.5062296e+09 | AR9: 6.1529229e+09 | AS9: 9.1295948e+09 | AT9: 8.9360793e+09 | AU9: 1.5285592e+10 | AV9: 1.7812705e+10 | AW9: 2.3552058e+10 | AX9: 3.6970901e+10 | AY9: 5.2381025e+10 | AZ9: 6.5266416e+10 | BA9: 8.8538665e+10 | BB9: 7.0307196e+10 | BC9: 8.1699527e+10 | BD9: 1.0943657e+11 | BE9: 1.2499821e+11 | BF9: 1.3340158e+11 | BG9: 1.3724444e+11 | BH9: 8.72193e+10 | BI9: 4.9840491e+10 | BJ9: 6.8972769e+10 | BK9: 7.7792944e+10 | BL9: 6.930911e+10 | BM9: 5.0241368e+10 | BN9: 6.5685435e+10 | BO9: 1.0671362e+11
A10: Albania | B10: ALB | C10: GDP (current US$) | D10: NY.GDP.MKTP.CD | AC10: 1.857338e+09 | AD10: 1.8970501e+09 | AE10: 2097326250 | AF10: 2080796250 | AG10: 2051236250 | AH10: 2253090000 | AI10: 2028553750 | AJ10: 1.099559e+09 | AK10: 6.5217499e+08 | AL10: 1.1853155e+09 | AM10: 1.8809509e+09 | AN10: 2.3927649e+09 | AO10: 3.1996408e+09 | AP10: 2.258514e+09 | AQ10: 2.5459645e+09 | AR10: 3.2121217e+09 | AS10: 3.4803553e+09 | AT10: 3.9221008e+09 | AU10: 4.3480682e+09 | AV10: 5.6114963e+09 | AW10: 7.1846858e+09 | AX10: 8.0520772e+09 | AY10: 8.896075e+09 | AZ10: 1.0677325e+10 | BA10: 1.2881353e+10 | BB10: 1.2044206e+10 | BC10: 1.1926927e+10 | BD10: 1.289076e+10 | BE10: 1.2319834e+10 | BF10: 1.2776225e+10 | BG10: 1.3228148e+10 | BH10: 1.1386853e+10 | BI10: 1.18612e+10 | BJ10: 1.3019726e+10 | BK10: 1.5156424e+10 | BL10: 1.5401826e+10 | BM10: 1.5162734e+10 | BN10: 1.7930565e+10 | BO10: 1.8882096e+10
A11: Andorra | B11: AND | C11: GDP (current US$) | D11: NY.GDP.MKTP.CD | O11: 78617623 | P11: 89406588 | Q11: 1.134144e+08 | R11: 1.5084157e+08 | S11: 1.8655716e+08 | T11: 2.2011288e+08 | U11: 2.2728406e+08 | V11: 2.53998e+08 | W11: 3.0802029e+08 | X11: 4.1154837e+08 | Y11: 4.4637757e+08 | Z11: 3.8898299e+08 | AA11: 3.7591481e+08 | AB11: 3.2784998e+08 | AC11: 3.3007306e+08 | AD11: 3.4674288e+08 | AE11: 4.8199619e+08 | AF11: 6.1130015e+08 | AG11: 7.2142597e+08 | AH11: 7.9548946e+08 | AI11: 1.0289894e+09 | AJ11: 1.106891e+09 | AK11: 1.2099926e+09 | AL11: 1.0070909e+09 | AM11: 1.0175447e+09 | AN11: 1.1787453e+09 | AO11: 1.2240234e+09 | AP11: 1.1806461e+09 | AQ11: 1.211954e+09 | AR11: 1.2398403e+09 | AS11: 1.4290481e+09 | AT11: 1.5469123e+09 | AU11: 1.7559899e+09 | AV11: 2.3616358e+09 | AW11: 2.8950476e+09 | AX11: 3.1598269e+09 | AY11: 3.4562651e+09 | AZ11: 3.9523977e+09 | BA11: 4.0857819e+09 | BB11: 3.6741882e+09 | BC11: 3.4499257e+09 | BD11: 3.6291336e+09 | BE11: 3.1886528e+09 | BF11: 3.193513e+09 | BG11: 3.2716856e+09 | BH11: 2.7898813e+09 | BI11: 2.8966105e+09 | BJ11: 3.0001621e+09 | BK11: 3.2184199e+09 | BL11: 3.1551493e+09 | BM11: 2.8910011e+09 | BN11: 3.3251454e+09 | BO11: 3.3520327e+09
A12: Arab World | B12: ARB | C12: GDP (current US$) | D12: NY.GDP.MKTP.CD | M12: 3.4715404e+10 | N12: 3.7827652e+10 | O12: 4.2768537e+10 | P12: 4.942852e+10 | Q12: 5.8935858e+10 | R12: 7.4780454e+10 | S12: 1.4213763e+11 | T12: 1.5706923e+11 | U12: 1.9551376e+11 | V12: 2.2567646e+11 | W12: 2.4960826e+11 | X12: 3.3796175e+11 | Y12: 4.598046e+11 | Z12: 4.7481214e+11 | AA12: 4.4457587e+11 | AB12: 4.1846207e+11 | AC12: 4.2589942e+11 | AD12: 4.1948544e+11 | AE12: 4.069827e+11 | AF12: 4.4060763e+11 | AG12: 4.2489619e+11 | AH12: 4.5582267e+11 | AI12: 6.4406257e+11 | AJ12: 4.7180008e+11 | AK12: 4.7381127e+11 | AL12: 4.8276426e+11 | AM12: 5.0776494e+11 | AN12: 5.560464e+11 | AO12: 6.1418609e+11 | AP12: 6.6230806e+11 | AQ12: 6.4919202e+11 | AR12: 7.1746944e+11 | AS12: 8.2018561e+11 | AT12: 8.0288111e+11 | AU12: 8.0796156e+11 | AV12: 8.9381803e+11 | AW12: 1.062737e+12 | AX12: 1.3044015e+12 | AY12: 1.5455391e+12 | AZ12: 1.7979322e+12 | BA12: 2.2630289e+12 | BB12: 1.9870534e+12 | BC12: 2.334638e+12 | BD12: 2.5559794e+12 | BE12: 2.8016976e+12 | BF12: 2.8596693e+12 | BG12: 2.9057327e+12 | BH12: 2.5541561e+12 | BI12: 2.5375367e+12 | BJ12: 2.6371115e+12 | BK12: 2.8434761e+12 | BL12: 2.8688909e+12 | BM12: 2.5333775e+12 | BN12: 2.9284555e+12 | BO12: 3.5575573e+12
A13: United Arab Emirates | B13: ARE | C13: GDP (current US$) | D13: NY.GDP.MKTP.CD | T13: 1.4720728e+10 | U13: 1.9213156e+10 | V13: 2.4871775e+10 | W13: 2.3775765e+10 | X13: 3.1225661e+10 | Y13: 4.359916e+10 | Z13: 4.9333424e+10 | AA13: 4.6622719e+10 | AB13: 4.2803323e+10 | AC13: 4.1807954e+10 | AD13: 4.060365e+10 | AE13: 3.3943612e+10 | AF13: 3.6384909e+10 | AG13: 3.6275674e+10 | AH13: 4.1464996e+10 | AI13: 5.0701444e+10 | AJ13: 5.1552166e+10 | AK13: 5.4239172e+10 | AL13: 5.562517e+10 | AM13: 5.9305094e+10 | AN13: 6.5743667e+10 | AO13: 7.3571234e+10 | AP13: 7.8839008e+10 | AQ13: 7.5674336e+10 | AR13: 8.4445473e+10 | AS13: 1.0433737e+11 | AT13: 1.0331164e+11 | AU13: 1.098162e+11 | AV13: 1.2434636e+11 | AW13: 1.4782437e+11 | AX13: 1.8061747e+11 | AY13: 2.2211654e+11 | AZ13: 2.5791613e+11 | BA13: 3.1547462e+11 | BB13: 2.5354736e+11 | BC13: 2.8978745e+11 | BD13: 3.5066606e+11 | BE13: 3.8461013e+11 | BF13: 4.0021853e+11 | BG13: 4.1410537e+11 | BH13: 3.7027547e+11 | BI13: 3.6925533e+11 | BJ13: 3.905168e+11 | BK13: 4.2704943e+11 | BL13: 4.1798972e+11 | BM13: 3.4947302e+11 | BN13: 4.1502159e+11 | BO13: 5.0753492e+11
A14: Argentina | B14: ARG | C14: GDP (current US$) | D14: NY.GDP.MKTP.CD | G14: 2.4450605e+10 | H14: 1.8272124e+10 | I14: 2.5605249e+10 | J14: 2.8344706e+10 | K14: 2.8630475e+10 | L14: 2.4256668e+10 | M14: 2.6436857e+10 | N14: 3.1256285e+10 | O14: 3.158421e+10 | P14: 3.3293199e+10 | Q14: 3.4733001e+10 | R14: 5.2544e+10 | S14: 7.2436777e+10 | T14: 5.2438648e+10 | U14: 5.11695e+10 | V14: 5.6781e+10 | W14: 8.9049453e+10 | X14: 6.9252329e+10 | Y14: 7.6961924e+10 | Z14: 7.8676842e+10 | AA14: 8.4307487e+10 | AB14: 1.0397911e+11 | AC14: 1.1691505e+11 | AD14: 8.8150892e+10 | AE14: 1.0587237e+11 | AF14: 1.0881089e+11 | AG14: 1.2689024e+11 | AH14: 7.6629729e+10 | AI14: 1.4135263e+11 | AJ14: 1.8971998e+11 | AK14: 2.2877899e+11 | AL14: 2.3674172e+11 | AM14: 257440000000 | AN14: 258031750000 | AO14: 272149750000 | AP14: 292859000000 | AQ14: 298948250000 | AR14: 283523000000 | AS14: 284203750000 | AT14: 268696750000 | AU14: 9.7724004e+10 | AV14: 1.2758697e+11 | AW14: 1.6465793e+11 | AX14: 1.987371e+11 | AY14: 2.3255726e+11 | AZ14: 2.8753051e+11 | BA14: 3.6155804e+11 | BB14: 3.3297648e+11 | BC14: 4.2362742e+11 | BD14: 5.3015818e+11 | BE14: 5.4598238e+11 | BF14: 5.5202514e+11 | BG14: 5.2631967e+11 | BH14: 5.9474929e+11 | BI14: 5.5753232e+11 | BJ14: 6.436284e+11 | BK14: 5.248199e+11 | BL14: 4.4775469e+11 | BM14: 3.8554041e+11 | BN14: 4.8722713e+11 | BO14: 6.3277028e+11
A15: Armenia | B15: ARM | C15: GDP (current US$) | D15: NY.GDP.MKTP.CD | AI15: 2.2568389e+09 | AJ15: 2.0698701e+09 | AK15: 1.2728355e+09 | AL15: 1.2013128e+09 | AM15: 1.3151586e+09 | AN15: 1.4683174e+09 | AO15: 1.5969689e+09 | AP15: 1.6394924e+09 | AQ15: 1.8937264e+09 | AR15: 1.8454822e+09 | AS15: 1.9115637e+09 | AT15: 2.1184679e+09 | AU15: 2.376335e+09 | AV15: 2.807061e+09 | AW15: 3.5766152e+09 | AX15: 4.9004695e+09 | AY15: 6.3844521e+09 | AZ15: 9.2063013e+09 | BA15: 1.1662041e+10 | BB15: 8.6479371e+09 | BC15: 9.2602858e+09 | BD15: 1.0142112e+10 | BE15: 1.0619321e+10 | BF15: 1.1121464e+10 | BG15: 1.1609513e+10 | BH15: 1.0553338e+10 | BI15: 1.0546136e+10 | BJ15: 1.1527459e+10 | BK15: 1.2457941e+10 | BL15: 1.3619291e+10 | BM15: 1.2641699e+10 | BN15: 1.386141e+10 | BO15: 1.9502784e+10
A16: American Samoa | B16: ASM | C16: GDP (current US$) | D16: NY.GDP.MKTP.CD | AU16: 512000000 | AV16: 524000000 | AW16: 509000000 | AX16: 500000000 | AY16: 493000000 | AZ16: 518000000 | BA16: 560000000 | BB16: 675000000 | BC16: 573000000 | BD16: 570000000 | BE16: 640000000 | BF16: 638000000 | BG16: 643000000 | BH16: 673000000 | BI16: 671000000 | BJ16: 612000000 | BK16: 639000000 | BL16: 647000000 | BM16: 716000000 | BN16: 709000000
A17: Antigua and Barbuda | B17: ATG | C17: GDP (current US$) | D17: NY.GDP.MKTP.CD | V17: 77496754 | W17: 87879341 | X17: 1.0907998e+08 | Y17: 1.3143103e+08 | Z17: 1.4784173e+08 | AA17: 1.6436928e+08 | AB17: 1.8214409e+08 | AC17: 2.0837285e+08 | AD17: 2.4092392e+08 | AE17: 2.9044014e+08 | AF17: 3.3717486e+08 | AG17: 3.9863773e+08 | AH17: 4.3879479e+08 | AI17: 4.5947037e+08 | AJ17: 4.8170741e+08 | AK17: 4.9928148e+08 | AL17: 5.3517407e+08 | AM17: 5.8942963e+08 | AN17: 5.7728148e+08 | AO17: 6.3372963e+08 | AP17: 6.8061852e+08 | AQ17: 7.2785926e+08 | AR17: 766200000 | AS17: 8.2637037e+08 | AT17: 8.0048148e+08 | AU17: 8.1438148e+08 | AV17: 8.563963e+08 | AW17: 9.1972963e+08 | AX17: 1.022963e+09 | AY17: 1.157663e+09 | AZ17: 1.3127593e+09 | BA17: 1.3700704e+09 | BB17: 1.2283296e+09 | BC17: 1148700000 | BD17: 1.137637e+09 | BE17: 1.1999481e+09 | BF17: 1.1814481e+09 | BG17: 1.2497333e+09 | BH17: 1.3366926e+09 | BI17: 1.4365852e+09 | BJ17: 1.4679556e+09 | BK17: 1.6047704e+09 | BL17: 1.6754037e+09 | BM17: 1.4163481e+09 | BN17: 1.5605185e+09 | BO17: 1.7576037e+09
A18: Australia | B18: AUS | C18: GDP (current US$) | D18: NY.GDP.MKTP.CD | E18: 1.8606563e+10 | F18: 1.9682883e+10 | G18: 1.9922563e+10 | H18: 2.1539843e+10 | I18: 2.3801124e+10 | J18: 2.5976164e+10 | K18: 2.7307844e+10 | L18: 3.0442725e+10 | M18: 3.2714085e+10 | N18: 3.6683366e+10 | O18: 4.1333607e+10 | P18: 4.5216647e+10 | Q18: 5.2042056e+10 | R18: 6.3832159e+10 | S18: 8.8963891e+10 | T18: 9.7304383e+10 | U18: 1.0506065e+11 | V18: 1.10351e+11 | W18: 1.1849158e+11 | X18: 1.3489833e+11 | Y18: 1.499844e+11 | Z18: 1.7689191e+11 | AA18: 1.9403729e+11 | AB18: 1.7726346e+11 | AC18: 1.9351725e+11 | AD18: 1.8063485e+11 | AE18: 1.8247202e+11 | AF18: 1.8948782e+11 | AG18: 2.3615253e+11 | AH18: 2.9987583e+11 | AI18: 3.1143063e+11 | AJ18: 3.2598164e+11 | AK18: 3.2553243e+11 | AL18: 3.1213814e+11 | AM18: 3.2280941e+11 | AN18: 3.6814078e+11 | AO18: 4.0131082e+11 | AP18: 4.3561377e+11 | AQ18: 3.9966086e+11 | AR18: 3.8938965e+11 | AS18: 4.1584497e+11 | AT18: 3.7935782e+11 | AU18: 3.9557303e+11 | AV18: 4.6749796e+11 | AW18: 6.1432636e+11 | AX18: 6.95305e+11 | AY18: 7.4790743e+11 | AZ18: 8.5442726e+11 | BA18: 1.0556861e+12 | BB18: 9.2862977e+11 | BC18: 1.1485695e+12 | BD18: 1.3984562e+12 | BE18: 1.5469527e+12 | BF18: 1.5763297e+12 | BG18: 1.4675899e+12 | BH18: 1.3505803e+12 | BI18: 1.2065629e+12 | BJ18: 1.3264675e+12 | BK18: 1.4282665e+12 | BL18: 1.3922185e+12 | BM18: 1.3269446e+12 | BN18: 1.5527032e+12 | BO18: 1.6754187e+12
A19: Austria | B19: AUT | C19: GDP (current US$) | D19: NY.GDP.MKTP.CD | E19: 6.5926938e+09 | F19: 7.3117496e+09 | G19: 7.7561102e+09 | H19: 8.3741753e+09 | I19: 9.1699839e+09 | J19: 9.9940706e+09 | K19: 1.0887682e+10 | L19: 1.1579432e+10 | M19: 1.2440625e+10 | N19: 1.3582799e+10 | O19: 1.5373006e+10 | P19: 1.7858486e+10 | Q19: 2.2059612e+10 | R19: 2.9515468e+10 | S19: 3.51893e+10 | T19: 4.0059207e+10 | U19: 4.2959976e+10 | V19: 5.1545759e+10 | W19: 6.2052259e+10 | X19: 7.3937297e+10 | Y19: 8.2058913e+10 | Z19: 7.1034228e+10 | AA19: 7.1275288e+10 | AB19: 7.2121017e+10 | AC19: 6.7985345e+10 | AD19: 6.9386774e+10 | AE19: 9.9036165e+10 | AF19: 1.2416844e+11 | AG19: 1.333394e+11 | AH19: 1.3310581e+11 | AI19: 1.6646339e+11 | AJ19: 1.7379418e+11 | AK19: 1.9507813e+11 | AL19: 1.9037972e+11 | AM19: 2.0353524e+11 | AN19: 2.4103828e+11 | AO19: 2.3725095e+11 | AP19: 2.1279035e+11 | AQ19: 2.182599e+11 | AR19: 2.1725915e+11 | AS19: 1.9728963e+11 | AT19: 1.9750877e+11 | AU19: 2.1439487e+11 | AV19: 2.6227363e+11 | AW19: 3.0145756e+11 | AX19: 3.1609227e+11 | AY19: 3.3628006e+11 | AZ19: 3.8918557e+11 | BA19: 4.3205194e+11 | BB19: 4.0175874e+11 | BC19: 3.9227511e+11 | BD19: 4.3168522e+11 | BE19: 4.0940182e+11 | BF19: 4.3019098e+11 | BG19: 4.4258482e+11 | BH19: 3.8197115e+11 | BI19: 3.9583735e+11 | BJ19: 4.1726115e+11 | BK19: 4.5499117e+11 | BL19: 4.4462118e+11 | BM19: 4.3522524e+11 | BN19: 4.803684e+11 | BO19: 4.7140007e+11
A20: Azerbaijan | B20: AZE | C20: GDP (current US$) | D20: NY.GDP.MKTP.CD | AI20: 8.858006e+09 | AJ20: 5344000000 | AK20: 4.4465867e+08 | AL20: 1.5703926e+09 | AM20: 1.1931411e+09 | AN20: 2.4173326e+09 | AO20: 3.176508e+09 | AP20: 3.9623624e+09 | AQ20: 4.4463704e+09 | AR20: 4.5812467e+09 | AS20: 5.2726172e+09 | AT20: 5.7076182e+09 | AU20: 6.2360867e+09 | AV20: 7.2764131e+09 | AW20: 8.6804102e+09 | AX20: 1.3245422e+10 | AY20: 2.0981929e+10 | AZ20: 3.3049427e+10 | BA20: 4.8851319e+10 | BB20: 4.4292409e+10 | BC20: 5.2909295e+10 | BD20: 6.5952764e+10 | BE20: 6.9679914e+10 | BF20: 7.4160553e+10 | BG20: 7.5239737e+10 | BH20: 5.3076245e+10 | BI20: 3.7867007e+10 | BJ20: 4.0866632e+10 | BK20: 4.7112479e+10 | BL20: 4.8174235e+10 | BM20: 42693000000 | BN20: 5.4825412e+10 | BO20: 7.8721059e+10
A21: Burundi | B21: BDI | C21: GDP (current US$) | D21: NY.GDP.MKTP.CD | E21: 1.9599999e+08 | F21: 2.0299999e+08 | G21: 2.1350001e+08 | H21: 2.3275e+08 | I21: 2.6075001e+08 | J21: 1.5899496e+08 | K21: 1.6544457e+08 | L21: 1.7829714e+08 | M21: 1.832e+08 | N21: 1.9020571e+08 | O21: 2.4273257e+08 | P21: 2.5284229e+08 | Q21: 2.4680457e+08 | R21: 3.0433984e+08 | S21: 3.4526349e+08 | T21: 4.2098667e+08 | U21: 4.4841275e+08 | V21: 5.4753556e+08 | W21: 6.1022556e+08 | X21: 7.8249667e+08 | Y21: 9.1972667e+08 | Z21: 9.6904667e+08 | AA21: 1.0132222e+09 | AB21: 1.0829263e+09 | AC21: 9.8714393e+08 | AD21: 1.1499793e+09 | AE21: 1.2017255e+09 | AF21: 1.1314665e+09 | AG21: 1.0824032e+09 | AH21: 1.1139241e+09 | AI21: 1.1321013e+09 | AJ21: 1.1673985e+09 | AK21: 1.0830377e+09 | AL21: 9.3863261e+08 | AM21: 9.2503059e+08 | AN21: 1.0004284e+09 | AO21: 8.6903386e+08 | AP21: 9.7289627e+08 | AQ21: 8.9377074e+08 | AR21: 8.0807722e+08 | AS21: 8.7048607e+08 | AT21: 8.7679472e+08 | AU21: 8.2539452e+08 | AV21: 7.8465442e+08 | AW21: 9.1525732e+08 | AX21: 1.1171131e+09 | AY21: 1.2733751e+09 | AZ21: 1.3561994e+09 | BA21: 1.6118359e+09 | BB21: 1.7814551e+09 | BC21: 2.0321352e+09 | BD21: 2.2358208e+09 | BE21: 2.3333413e+09 | BF21: 2.4516066e+09 | BG21: 2.7057833e+09 | BH21: 3.1040035e+09 | BI21: 2.6444878e+09 | BJ21: 2.723587e+09 | BK21: 2.6671822e+09 | BL21: 2.5765189e+09 | BM21: 2.6496803e+09 | BN21: 2.7757987e+09 | BO21: 3.0734147e+09
A22: Belgium | B22: BEL | C22: GDP (current US$) | D22: NY.GDP.MKTP.CD | E22: 1.1658723e+10 | F22: 1.2400145e+10 | G22: 1.3264016e+10 | H22: 1.4260017e+10 | I22: 1.5960107e+10 | J22: 1.7371458e+10 | K22: 1.8651883e+10 | L22: 1.9992041e+10 | M22: 2.1376353e+10 | N22: 2.3710736e+10 | O22: 2.6706196e+10 | P22: 2.9821662e+10 | Q22: 3.7209418e+10 | R22: 4.7743801e+10 | S22: 5.6033078e+10 | T22: 6.5678189e+10 | U22: 7.1113883e+10 | V22: 8.2839905e+10 | W22: 1.0124653e+11 | X22: 1.1631546e+11 | Y22: 1.2682931e+11 | Z22: 1.0473002e+11 | AA22: 9.2095926e+10 | AB22: 8.7184239e+10 | AC22: 8.334953e+10 | AD22: 8.6268264e+10 | AE22: 1.2001879e+11 | AF22: 1.493944e+11 | AG22: 1.622991e+11 | AH22: 1.6422106e+11 | AI22: 2.0533175e+11 | AJ22: 2.10511e+11 | AK22: 2.3478165e+11 | AL22: 2.247218e+11 | AM22: 2.4488413e+11 | AN22: 2.8802559e+11 | AO22: 2.7920143e+11 | AP22: 2.5270805e+11 | AQ22: 2.5852834e+11 | AR22: 2.5824573e+11 | AS22: 2.3679246e+11 | AT22: 2.3674614e+11 | AU22: 2.583836e+11 | AV22: 3.1808253e+11 | AW22: 3.6921471e+11 | AX22: 3.8571476e+11 | AY22: 4.0825984e+11 | AZ22: 4.7092216e+11 | BA22: 5.1732809e+11 | BB22: 4.8325417e+11 | BC22: 4.8142088e+11 | BD22: 5.2333035e+11 | BE22: 4.9615288e+11 | BF22: 5.2179102e+11 | BG22: 5.353902e+11 | BH22: 4.6233557e+11 | BI22: 4.7606276e+11 | BJ22: 5.0276472e+11 | BK22: 5.4329907e+11 | BL22: 5.3586569e+11 | BM22: 5.2521307e+11 | BN22: 5.9435196e+11 | BO22: 5.786041e+11
A23: Benin | B23: BEN | C23: GDP (current US$) | D23: NY.GDP.MKTP.CD | E23: 2.2619558e+08 | F23: 2.3566822e+08 | G23: 2.3643495e+08 | H23: 2.539277e+08 | I23: 2.6981901e+08 | J23: 2.8990868e+08 | K23: 3.0292524e+08 | L23: 3.0622195e+08 | M23: 3.2632311e+08 | N23: 3.3074824e+08 | O23: 3.3362771e+08 | P23: 3.3507303e+08 | Q23: 4.1033186e+08 | R23: 5.0437607e+08 | S23: 5.5465486e+08 | T23: 6.7687014e+08 | U23: 6.9840826e+08 | V23: 7.5004978e+08 | W23: 9.2884347e+08 | X23: 1.186231e+09 | Y23: 1.4052518e+09 | Z23: 1.2911202e+09 | AA23: 1.2677787e+09 | AB23: 1.0953482e+09 | AC23: 1.051134e+09 | AD23: 1.0457128e+09 | AE23: 1.336102e+09 | AF23: 1.5624122e+09 | AG23: 1.6202461e+09 | AH23: 1.5022944e+09 | AI23: 1.9599653e+09 | AJ23: 1.9864378e+09 | AK23: 1.6953153e+09 | AL23: 2.2745581e+09 | AM23: 1.5980759e+09 | AN23: 2.1696271e+09 | AO23: 2.3611164e+09 | AP23: 2.2683016e+09 | AQ23: 2.4550927e+09 | AR23: 3.677394e+09 | AS23: 3.5199914e+09 | AT23: 3.6662226e+09 | AU23: 4.1943427e+09 | AV23: 5.3492581e+09 | AW23: 6.1902704e+09 | AX23: 6.567655e+09 | AY23: 7.0341113e+09 | AZ23: 8.1690484e+09 | BA23: 9.7877345e+09 | BB23: 9.7386265e+09 | BC23: 9.535345e+09 | BD23: 1.0693321e+10 | BE23: 1.1141358e+10 | BF23: 1.2517845e+10 | BG23: 1.3284528e+10 | BH23: 1.1388161e+10 | BI23: 1.1821066e+10 | BJ23: 1.2701656e+10 | BK23: 1.4262408e+10 | BL23: 1.4391686e+10 | BM23: 1.5651545e+10 | BN23: 1.7690084e+10 | BO23: 1.7401746e+10
A24: Burkina Faso | B24: BFA | C24: GDP (current US$) | D24: NY.GDP.MKTP.CD | E24: 3.3044282e+08 | F24: 3.5024723e+08 | G24: 3.795671e+08 | H24: 3.9404067e+08 | I24: 4.1032164e+08 | J24: 4.2291679e+08 | K24: 4.3388977e+08 | L24: 4.5075392e+08 | M24: 4.6044269e+08 | N24: 4.7829864e+08 | O24: 4.5840427e+08 | P24: 4.8241118e+08 | Q24: 5.7859552e+08 | R24: 6.7477357e+08 | S24: 7.5113343e+08 | T24: 9.399727e+08 | U24: 9.7654719e+08 | V24: 1.1312249e+09 | W24: 1.4755836e+09 | X24: 1.7484806e+09 | Y24: 1.9287199e+09 | Z24: 1.7758423e+09 | AA24: 1.7544501e+09 | AB24: 1.6002786e+09 | AC24: 1.4598801e+09 | AD24: 1.5524932e+09 | AE24: 2.0363034e+09 | AF24: 2.3698349e+09 | AG24: 2.6160405e+09 | AH24: 2.6155877e+09 | AI24: 3.1013008e+09 | AJ24: 3.1350456e+09 | AK24: 3.3566925e+09 | AL24: 3.1995365e+09 | AM24: 1.8952906e+09 | AN24: 2.379518e+09 | AO24: 2.5865506e+09 | AP24: 2.4476691e+09 | AQ24: 2.8049024e+09 | AR24: 3.3895667e+09 | AS24: 2.9683701e+09 | AT24: 3.1903711e+09 | AU24: 3.6223501e+09 | AV24: 4.7407681e+09 | AW24: 5.4516885e+09 | AX24: 6.1463532e+09 | AY24: 6.5474198e+09 | AZ24: 7.6257228e+09 | BA24: 9.4514355e+09 | BB24: 9.4506969e+09 | BC24: 1.010962e+10 | BD24: 1.2080296e+10 | BE24: 1.2561015e+10 | BF24: 1.34443e+10 | BG24: 1.3943016e+10 | BH24: 1.1832159e+10 | BI24: 1.2833363e+10 | BJ24: 1.4106956e+10 | BK24: 1.5890066e+10 | BL24: 1.6178162e+10 | BM24: 1.7933606e+10 | BN24: 1.9737616e+10 | BO24: 1.888462e+10
A25: Bangladesh | B25: BGD | C25: GDP (current US$) | D25: NY.GDP.MKTP.CD | E25: 4.2748939e+09 | F25: 4.8175802e+09 | G25: 5.0814133e+09 | H25: 5.3194584e+09 | I25: 5.3860546e+09 | J25: 5.9066366e+09 | K25: 6.4396876e+09 | L25: 7.2535754e+09 | M25: 7.4836855e+09 | N25: 8.4710061e+09 | O25: 8.9927218e+09 | P25: 8.7518428e+09 | Q25: 6.2882459e+09 | R25: 8.0867257e+09 | S25: 1.2512461e+10 | T25: 1.9448348e+10 | U25: 1.0117113e+10 | V25: 9.6511493e+09 | W25: 1.3281767e+10 | X25: 1.556548e+10 | Y25: 1.8138049e+10 | Z25: 2.0249694e+10 | AA25: 1.8525399e+10 | AB25: 1.7609049e+10 | AC25: 18920840000 | AD25: 2.2278423e+10 | AE25: 2.1774033e+10 | AF25: 2.4298032e+10 | AG25: 2.6579006e+10 | AH25: 2.8781715e+10 | AI25: 3.1598341e+10 | AJ25: 3.0957484e+10 | AK25: 3.1708875e+10 | AL25: 3.3166519e+10 | AM25: 3.3768661e+10 | AN25: 3.7939749e+10 | AO25: 4.6438484e+10 | AP25: 4.8244309e+10 | AQ25: 4.9984559e+10 | AR25: 5.127057e+10 | AS25: 5.3369787e+10 | AT25: 5.399129e+10 | AU25: 5.4724081e+10 | AV25: 6.0158929e+10 | AW25: 6.5108544e+10 | AX25: 6.9442943e+10 | AY25: 7.1819084e+10 | AZ25: 7.9611888e+10 | BA25: 9.1631278e+10 | BB25: 1.0247778e+11 | BC25: 1.1527908e+11 | BD25: 1.2863798e+11 | BE25: 1.3335582e+11 | BF25: 1.4999053e+11 | BG25: 1.7288543e+11 | BH25: 1.9507857e+11 | BI25: 2.6523639e+11 | BJ25: 2.9375477e+11 | BK25: 3.2137916e+11 | BL25: 3.512384e+11 | BM25: 3.739022e+11 | BN25: 4.162648e+11 | BO25: 4.60201e+11
A26: Bulgaria | B26: BGR | C26: GDP (current US$) | D26: NY.GDP.MKTP.CD | Y26: 1.9839231e+10 | Z26: 19870000000 | AA26: 19342000000 | AB26: 1.6563667e+10 | AC26: 1.7594944e+10 | AD26: 1.7155421e+10 | AE26: 2.0249294e+10 | AF26: 28101000000 | AG26: 2.2555941e+10 | AH26: 2.1988444e+10 | AI26: 2.0632091e+10 | AJ26: 1.0943548e+10 | AK26: 1.0350515e+10 | AL26: 1.0832229e+10 | AM26: 9.697417e+09 | AN26: 1.8991532e+10 | AO26: 1.2294988e+10 | AP26: 1.1316126e+10 | AQ26: 1.5031052e+10 | AR26: 1.3627325e+10 | AS26: 1.324599e+10 | AT26: 1.4183444e+10 | AU26: 1.6403044e+10 | AV26: 2.1144962e+10 | AW26: 2.6157745e+10 | AX26: 2.9868652e+10 | AY26: 3.4380544e+10 | AZ26: 4.4432812e+10 | BA26: 5.4480698e+10 | BB26: 5.2023814e+10 | BC26: 5.0754204e+10 | BD26: 5.773571e+10 | BE26: 5.4290156e+10 | BF26: 5.5844245e+10 | BG26: 5.7159558e+10 | BH26: 5.0828089e+10 | BI26: 5.3987487e+10 | BJ26: 5.9343061e+10 | BK26: 6.6399602e+10 | BL26: 6.8911931e+10 | BM26: 7.0404359e+10 | BN26: 8.4061396e+10 | BO26: 8.9040398e+10
A27: Bahrain | B27: BHR | C27: GDP (current US$) | D27: NY.GDP.MKTP.CD | Y27: 3.0726983e+09 | Z27: 3.4678192e+09 | AA27: 3.6457447e+09 | AB27: 3.7351064e+09 | AC27: 3.9055851e+09 | AD27: 3.6518617e+09 | AE27: 3.0523936e+09 | AF27: 3.392021e+09 | AG27: 3.7023936e+09 | AH27: 3.8635638e+09 | AI27: 4.2297872e+09 | AJ27: 4.6162234e+09 | AK27: 4.7510638e+09 | AL27: 5.2002661e+09 | AM27: 5.567554e+09 | AN27: 5.8494683e+09 | AO27: 6.101862e+09 | AP27: 6.349203e+09 | AQ27: 6.1837772e+09 | AR27: 6.6210107e+09 | AS27: 9.0628989e+09 | AT27: 8.9761968e+09 | AU27: 9.5935106e+09 | AV27: 1.1074814e+10 | AW27: 1.315016e+10 | AX27: 1.5968723e+10 | AY27: 1.8504761e+10 | AZ27: 21730000000 | BA27: 2.5710904e+10 | BB27: 2.2938218e+10 | BC27: 2.5713271e+10 | BD27: 2.8776596e+10 | BE27: 3.0749309e+10 | BF27: 3.2539468e+10 | BG27: 3.3387713e+10 | BH27: 3.1050638e+10 | BI27: 3.2234973e+10 | BJ27: 3.5473777e+10 | BK27: 3.7802005e+10 | BL27: 3.8653318e+10 | BM27: 3.4621808e+10 | BN27: 3.9303404e+10 | BO27: 4.439082e+10
A28: Bahamas, The | B28: BHS | C28: GDP (current US$) | D28: NY.GDP.MKTP.CD | E28: 1.6980392e+08 | F28: 1.9009804e+08 | G28: 2.122549e+08 | H28: 2.377451e+08 | I28: 2.6666667e+08 | J28: 3.0039216e+08 | K28: 340000000 | L28: 3.9019608e+08 | M28: 4.4490196e+08 | N28: 5.2813725e+08 | O28: 5.3842315e+08 | P28: 573400000 | Q28: 590900000 | R28: 670900000 | S28: 632400000 | T28: 596200000 | U28: 642100000 | V28: 713000000 | W28: 832400000 | X28: 1139800100 | Y28: 1335300000 | Z28: 1426500000 | AA28: 1578300000 | AB28: 1732800000 | AC28: 2041100000 | AD28: 2320699900 | AE28: 2472500000 | AF28: 2713999900 | AG28: 2817900000 | AH28: 3062000000 | AI28: 3166000000 | AJ28: 3111160000 | AK28: 3109000000 | AL28: 3092000000 | AM28: 3259000000 | AN28: 3429000000 | AO28: 3609000000 | AP28: 6332360000 | AQ28: 6833220000 | AR28: 7683870000 | AS28: 8076470000 | AT28: 8317830000 | AU28: 8881160000 | AV28: 8870090000 | AW28: 9055290000 | AX28: 9836200000 | AY28: 10167250000 | AZ28: 10618340000 | BA28: 10526000000 | BB28: 9981960000 | BC28: 10095760000 | BD28: 10070450000 | BE28: 10720500000 | BF28: 10562800000 | BG28: 11176100000 | BH28: 11672900000 | BI28: 11750800000 | BJ28: 12253500000 | BK28: 12653600000 | BL28: 13058700000 | BM28: 9754600000 | BN28: 11527600000 | BO28: 12897400000
A29: Bosnia and Herzegovina | B29: BIH | C29: GDP (current US$) | D29: NY.GDP.MKTP.CD | AM29: 1.2558025e+09 | AN29: 1.866573e+09 | AO29: 2.7860453e+09 | AP29: 3.67191e+09 | AQ29: 4.1167753e+09 | AR29: 4.6862554e+09 | AS29: 5.567774e+09 | AT29: 5.8006166e+09 | AU29: 6.7282195e+09 | AV29: 8.4988934e+09 | AW29: 1.0156541e+10 | AX29: 1.1222796e+10 | AY29: 1.2864842e+10 | AZ29: 1.5778737e+10 | BA29: 1.9112801e+10 | BB29: 1.7613946e+10 | BC29: 1.7176321e+10 | BD29: 1.8644239e+10 | BE29: 1.7226736e+10 | BF29: 1.8179105e+10 | BG29: 1.8558731e+10 | BH29: 1.6404352e+10 | BI29: 1.7116926e+10 | BJ29: 1.8326376e+10 | BK29: 2.0484048e+10 | BL29: 2.0482603e+10 | BM29: 2.0226031e+10 | BN29: 2.3649566e+10 | BO29: 2.4527507e+10
A30: Belarus | B30: BLR | C30: GDP (current US$) | D30: NY.GDP.MKTP.CD | AI30: 21650000000 | AJ30: 18000000000 | AK30: 1.7037037e+10 | AL30: 1.6280992e+10 | AM30: 1.4932024e+10 | AN30: 1.3972677e+10 | AO30: 1.4756846e+10 | AP30: 1.4128409e+10 | AQ30: 1.5222013e+10 | AR30: 1.2138487e+10 | AS30: 1.2736857e+10 | AT30: 1.235482e+10 | AU30: 1.4594928e+10 | AV30: 1.7825437e+10 | AW30: 2.3141593e+10 | AX30: 3.0210092e+10 | AY30: 3.6961822e+10 | AZ30: 4.5275747e+10 | BA30: 6.0752177e+10 | BB30: 5.0873182e+10 | BC30: 5.7231905e+10 | BD30: 6.1762341e+10 | BE30: 6.5685904e+10 | BF30: 7.5527538e+10 | BG30: 7.8812786e+10 | BH30: 5.6454895e+10 | BI30: 4.7723549e+10 | BJ30: 5.4725312e+10 | BK30: 6.0031164e+10 | BL30: 6.4410113e+10 | BM30: 6.1371755e+10 | BN30: 6.9673747e+10 | BO30: 7.2793458e+10
A31: Belize | B31: BLZ | C31: GDP (current US$) | D31: NY.GDP.MKTP.CD | E31: 28072478 | F31: 29965000 | G31: 31857592 | H31: 33750114 | I31: 36194586 | J31: 40110040 | K31: 44450044 | L31: 47431267 | M31: 44999910 | N31: 47399905 | O31: 53339893 | P31: 59074683 | Q31: 65998076 | R31: 78214778 | S31: 1.0316046e+08 | T31: 1.1819405e+08 | U31: 97094221 | V31: 117650000 | W31: 136300000 | X31: 151800000 | Y31: 1.9793822e+08 | Z31: 1.9608985e+08 | AA31: 1.8220633e+08 | AB31: 1.9210319e+08 | AC31: 2.1438195e+08 | AD31: 2.1264374e+08 | AE31: 2.3163832e+08 | AF31: 2.8108256e+08 | AG31: 3.2009336e+08 | AH31: 3.6913389e+08 | AI31: 549500000 | AJ31: 599000000 | AK31: 693500000 | AL31: 751000000 | AM31: 771500000 | AN31: 818500000 | AO31: 851500000 | AP31: 868000000 | AQ31: 914000000 | AR31: 975000000 | AS31: 1116000000 | AT31: 1163000000 | AU31: 1233000000 | AV31: 1298000000 | AW31: 1389500000 | AX31: 1461500000 | AY31: 1581000000 | AZ31: 1696000000 | BA31: 1729000000 | BB31: 1680500000 | BC31: 1738500000 | BD31: 1819500000 | BE31: 1903000000 | BF31: 2029500000 | BG31: 2138000000 | BH31: 2210500000 | BI31: 2258500000 | BJ31: 2286000000 | BK31: 2315000000 | BL31: 2416500000 | BM31: 2080000000 | BN31: 2491500000 | BO31: 2.8240818e+09
A32: Bermuda | B32: BMU | C32: GDP (current US$) | D32: NY.GDP.MKTP.CD | E32: 84466654 | F32: 89249987 | G32: 94149986 | H32: 96366652 | I32: 1.0756665e+08 | J32: 1.1433905e+08 | K32: 1.3417337e+08 | L32: 1.5510298e+08 | M32: 150000000 | N32: 164900000 | O32: 186300000 | P32: 211100000 | Q32: 235400000 | R32: 269500000 | S32: 312600000 | T32: 345000000 | U32: 386300000 | V32: 447000000 | W32: 475800000 | X32: 517200000 | Y32: 613299968 | Z32: 739100032 | AA32: 785500032 | AB32: 889400000 | AC32: 985699968 | AD32: 1039500032 | AE32: 1173500032 | AF32: 1296499968 | AG32: 1415100032 | AH32: 1501500032 | AI32: 1592400000 | AJ32: 1634900000 | AK32: 1679900000 | AL32: 1820359900 | AM32: 1867160100 | AN32: 2030750000 | AO32: 2695390000 | AP32: 2932827000 | AQ32: 3130748000 | AR32: 3324433000 | AS32: 3480219000 | AT32: 3680483000 | AU32: 3937228000 | AV32: 4186525000 | AW32: 4484703000 | AX32: 4868136000 | AY32: 6144000000 | AZ32: 6767000000 | BA32: 6980000000 | BB32: 6656000000 | BC32: 6634526000 | BD32: 6312691000 | BE32: 6378188000 | BF32: 6465756000 | BG32: 6413988000 | BH32: 6654541000 | BI32: 6899911000 | BJ32: 7142316000 | BK32: 7225977000 | BL32: 7423465000 | BM32: 6887147000 | BN32: 7127200000 | BO32: 7550500000
A33: Bolivia | B33: BOL | C33: GDP (current US$) | D33: NY.GDP.MKTP.CD | E33: 3.770202e+08 | F33: 4.1010101e+08 | G33: 4.4840067e+08 | H33: 4.8282828e+08 | I33: 5.4402357e+08 | J33: 6.043771e+08 | K33: 6.6919192e+08 | L33: 7.5580808e+08 | M33: 8.5791246e+08 | N33: 9.2962963e+08 | O33: 1.0170034e+09 | P33: 1.0956229e+09 | Q33: 1.2576156e+09 | R33: 1.2629685e+09 | S33: 2.1002499e+09 | T33: 2.4046977e+09 | U33: 2.731984e+09 | V33: 3.2274363e+09 | W33: 3.7582209e+09 | X33: 4.4213364e+09 | Y33: 4.5374878e+09 | Z33: 5.8916067e+09 | AA33: 5.5941213e+09 | AB33: 5.4226563e+09 | AC33: 6.1694832e+09 | AD33: 5.3772766e+09 | AE33: 3.9593828e+09 | AF33: 4.3479563e+09 | AG33: 4.5976124e+09 | AH33: 4.7159729e+09 | AI33: 4.8675826e+09 | AJ33: 5.343262e+09 | AK33: 5.6438692e+09 | AL33: 5.734699e+09 | AM33: 5.9812233e+09 | AN33: 6.7151622e+09 | AO33: 7.3969484e+09 | AP33: 7.9257363e+09 | AQ33: 8.4974941e+09 | AR33: 8.285064e+09 | AS33: 8.3978559e+09 | AT33: 8.1415173e+09 | AU33: 7.9054851e+09 | AV33: 8.0824e+09 | AW33: 8.7734518e+09 | AX33: 9.5491223e+09 | AY33: 1.1451845e+10 | AZ33: 1.3120108e+10 | BA33: 1.6674277e+10 | BB33: 1.7339992e+10 | BC33: 1.9649725e+10 | BD33: 2.3963163e+10 | BE33: 2.7084497e+10 | BF33: 3.0659339e+10 | BG33: 3.2996188e+10 | BH33: 3.3000198e+10 | BI33: 3.3941126e+10 | BJ33: 3.7508642e+10 | BK33: 4.0287648e+10 | BL33: 4.0895323e+10 | BM33: 3.6629844e+10 | BN33: 4.0408209e+10 | BO33: 4.3068886e+10
A34: Brazil | B34: BRA | C34: GDP (current US$) | D34: NY.GDP.MKTP.CD | E34: 1.7030466e+10 | F34: 1.727594e+10 | G34: 1.9231748e+10 | H34: 2.3287713e+10 | I34: 2.0963734e+10 | J34: 2.2465523e+10 | K34: 2.8283324e+10 | L34: 3.1086389e+10 | M34: 3.3930457e+10 | N34: 3.7171641e+10 | O34: 4.2327665e+10 | P34: 4.8869831e+10 | Q34: 5.8434858e+10 | R34: 8.3592276e+10 | S34: 1.0979452e+11 | T34: 1.2920356e+11 | U34: 1.5316895e+11 | V34: 1.763441e+11 | W34: 2.0027865e+11 | X34: 2.213382e+11 | Y34: 2.3739349e+11 | Z34: 2.5801517e+11 | AA34: 2.7131411e+11 | AB34: 1.8965651e+11 | AC34: 1.8833997e+11 | AD34: 2.1087984e+11 | AE34: 2.5648085e+11 | AF34: 2.8305684e+11 | AG34: 3.0788193e+11 | AH34: 4.1299082e+11 | AI34: 4.649891e+11 | AJ34: 4.0772905e+11 | AK34: 3.9056656e+11 | AL34: 4.382995e+11 | AM34: 5.4622975e+11 | AN34: 7.6933333e+11 | AO34: 8.5042643e+11 | AP34: 8.8320645e+11 | AQ34: 8.6371101e+11 | AR34: 5.9964208e+11 | AS34: 6.5544819e+11 | AT34: 5.599837e+11 | AU34: 5.0979527e+11 | AV34: 5.5823372e+11 | AW34: 6.6928932e+11 | AX34: 8.9163383e+11 | AY34: 1.1076267e+12 | AZ34: 1.3971142e+12 | BA34: 1.6958554e+12 | BB34: 1.6669963e+12 | BC34: 2.2088381e+12 | BD34: 2.6161566e+12 | BE34: 2.4652283e+12 | BF34: 2472819362259 | BG34: 2.4560438e+12 | BH34: 1.802212e+12 | BI34: 1.7956933e+12 | BJ34: 2.0635147e+12 | BK34: 1.9169337e+12 | BL34: 1.8732882e+12 | BM34: 1.4761073e+12 | BN34: 1.649623e+12 | BO34: 1.9200956e+12
A35: Barbados | B35: BRB | C35: GDP (current US$) | D35: NY.GDP.MKTP.CD | S35: 3.1180464e+08 | T35: 4.0217861e+08 | U35: 4.3591127e+08 | V35: 4.9509767e+08 | W35: 5.5288371e+08 | X35: 6.7036245e+08 | Y35: 1.0122806e+09 | Z35: 1.1142047e+09 | AA35: 1.1639238e+09 | AB35: 1.2360165e+09 | AC35: 1.3468901e+09 | AD35: 1.4095361e+09 | AE35: 1.5477552e+09 | AF35: 1.7043703e+09 | AG35: 1.8127579e+09 | AH35: 2.0061652e+09 | AI35: 2.0121315e+09 | AJ35: 2.0205837e+09 | AK35: 1957000000 | AL35: 2.0633421e+09 | AM35: 2.1513449e+09 | AN35: 2.2169741e+09 | AO35: 2.3636454e+09 | AP35: 2.4983841e+09 | AQ35: 2.8170835e+09 | AR35: 2.9518222e+09 | AS35: 3059500000 | AT35: 3054500000 | AU35: 3106500000 | AV35: 3209500000 | AW35: 3444500000 | AX35: 3819500000 | AY35: 4217450800 | AZ35: 4674007450 | BA35: 4784925100 | BB35: 4465657300 | BC35: 4529928300 | BD35: 4657699450 | BE35: 4610096000 | BF35: 4677248300 | BG35: 4696344350 | BH35: 4724691200 | BI35: 4832811750 | BJ35: 4981588900 | BK35: 5097283200 | BL35: 5324250000 | BM35: 4671800000 | BN35: 4843800000 | BO35: 5.6379145e+09
A36: Brunei Darussalam | B36: BRN | C36: GDP (current US$) | D36: NY.GDP.MKTP.CD | J36: 1.140395e+08 | K36: 1.3275753e+08 | L36: 1.3902954e+08 | M36: 1.6081824e+08 | N36: 1.6121024e+08 | O36: 1.7907893e+08 | P36: 1.9752574e+08 | Q36: 2.7082279e+08 | R36: 4.3309559e+08 | S36: 1.0735918e+09 | T36: 1.1683043e+09 | U36: 1.4230374e+09 | V36: 1.7327212e+09 | W36: 1.9415794e+09 | X36: 2.8038337e+09 | Y36: 4.9288058e+09 | Z36: 4.3662311e+09 | AA36: 4.2642025e+09 | AB36: 3.8446322e+09 | AC36: 3.7825526e+09 | AD36: 3.5235325e+09 | AE36: 2.3585748e+09 | AF36: 2.7544852e+09 | AG36: 2.6906841e+09 | AH36: 2.9855318e+09 | AI36: 3.520487e+09 | AJ36: 3.7017742e+09 | AK36: 4.1836338e+09 | AL36: 4.1057294e+09 | AM36: 4.0872198e+09 | AN36: 4.7341035e+09 | AO36: 5.1154547e+09 | AP36: 5.1973126e+09 | AQ36: 4.0511432e+09 | AR36: 4.6001176e+09 | AS36: 6.0012809e+09 | AT36: 5.6010202e+09 | AU36: 5.8433672e+09 | AV36: 6.5573958e+09 | AW36: 7.8722013e+09 | AX36: 9.5314172e+09 | AY36: 1.1470462e+10 | AZ36: 1.2247681e+10 | BA36: 1.4393438e+10 | BB36: 1.0732593e+10 | BC36: 1.3707275e+10 | BD36: 1.8525128e+10 | BE36: 1.9048443e+10 | BF36: 1.8094326e+10 | BG36: 1.7097801e+10 | BH36: 1.2930293e+10 | BI36: 1.1400467e+10 | BJ36: 1.2128182e+10 | BK36: 1.3567164e+10 | BL36: 1.346924e+10 | BM36: 1.2005796e+10 | BN36: 1.4006497e+10 | BO36: 1.6681532e+10
